<?xml version="1.0" ?>
<!-- =================================================================================== -->
<!-- |    This document was autogenerated by xacro from sketch_bot.xacro               | -->
<!-- |    EDITING THIS FILE BY HAND IS NOT RECOMMENDED                                 | -->
<!-- =================================================================================== -->
<robot name="sketch_bot">
  <material name="dark_yellow">
    <color rgba="0.75 0.55 0.15 1.0"/>
  </material>
  <material name="white">
    <color rgba="1.0 1.0 1.0 1.0"/>
  </material>
  <material name="dark_grey">
    <color rgba="0.1 0.1 0.1 1.0"/>
  </material>
  <link name="base_link">
    <visual>
      <origin rpy="0 0 0.0" xyz="0 0 0"/>
      <geometry>
        <mesh filename="package://sketch_bot_support/meshes/visual/base_link.stl" scale="1.0 1.0 1.0"/>
      </geometry>
      <material name="dark_grey"/>
    </visual>
    <collision>
      <origin rpy="0 0 0.0" xyz="0 0 0"/>
      <geometry>
        <mesh filename="package://sketch_bot_support/meshes/collision/base_link.stl" scale="1.0 1.0 1.0"/>
      </geometry>
    </collision>
  </link>
  <link name="link_1">
    <visual>
      <origin rpy="0 0 0.0" xyz="0 0 0"/>
      <geometry>
        <mesh filename="package://sketch_bot_support/meshes/visual/link_1.stl" scale="1.0 1.0 1.0"/>
      </geometry>
      <material name="white"/>
    </visual>
    <collision>
      <origin rpy="0 0 0.0" xyz="0 0 0"/>
      <geometry>
        <mesh filename="package://sketch_bot_support/meshes/collision/link_1.stl" scale="1.0 1.0 1.0"/>
      </geometry>
    </collision>
  </link>
  <link name="link_2">
    <visual>
      <origin rpy="0 0 0.0" xyz="0 0 -0.15785"/>
      <geometry>
        <mesh filename="package://sketch_bot_support/meshes/visual/link_2.stl" scale="1.0 1.0 1.0"/>
      </geometry>
      <material name="dark_yellow"/>
    </visual>
    <collision>
      <origin rpy="0 0 0.0" xyz="0 0 -0.15785"/>
      <geometry>
        <mesh filename="package://sketch_bot_support/meshes/collision/link_2.stl" scale="1.0 1.0 1.0"/>
      </geometry>
    </collision>
  </link>
  <link name="link_3">
    <visual>
      <origin rpy="0 0 0.0" xyz="0 0 -0.51345"/>
      <geometry>
        <mesh filename="package://sketch_bot_support/meshes/visual/link_3.stl" scale="1.0 1.0 1.0"/>
      </geometry>
      <material name="white"/>
    </visual>
    <collision>
      <origin rpy="0 0 0.0" xyz="0 0 -0.51345"/>
      <geometry>
        <mesh filename="package://sketch_bot_support/meshes/collision/link_3.stl" scale="1.0 1.0 1.0"/>
      </geometry>
    </collision>
  </link>
  <link name="link_4">
    <visual>
      <origin rpy="0 0 0.0" xyz="0 0 -0.865579"/>
      <geometry>
        <mesh filename="package://sketch_bot_support/meshes/visual/link_4.stl" scale="1.0 1.0 1.0"/>
      </geometry>
      <material name="dark_yellow"/>
    </visual>
    <collision>
      <origin rpy="0 0 0.0" xyz="0 0 -0.865579"/>
      <geometry>
        <mesh filename="package://sketch_bot_support/meshes/collision/link_4.stl" scale="1.0 1.0 1.0"/>
      </geometry>
    </collision>
  </link>
  <joint name="joint_1" type="revolute">
    <origin rpy="0 0 0" xyz="0 0 0"/>
    <parent link="base_link"/>
    <child link="link_1"/>
    <axis xyz="0 0 1"/>
    <limit effort="0" lower="-3.141592653589793" upper="3.141592653589793" velocity="2.0943951023931953"/>
  </joint>
  <joint name="joint_2" type="revolute">
    <origin rpy="0 0 0" xyz="0 0 0.15785"/>
    <parent link="link_1"/>
    <child link="link_2"/>
    <axis xyz="-1 0 0"/>
    <limit effort="0" lower="-3.141592653589793" upper="3.141592653589793" velocity="2.0943951023931953"/>
  </joint>
  <joint name="joint_3" type="revolute">
    <origin rpy="0 0 0" xyz="0 0 0.3556"/>
    <parent link="link_2"/>
    <child link="link_3"/>
    <axis xyz="-1 0 0"/>
    <limit effort="0" lower="-3.141592653589793" upper="3.141592653589793" velocity="2.0943951023931953"/>
  </joint>
  <joint name="joint_4" type="revolute">
    <origin rpy="0 0 0" xyz="0 0 0.352129"/>
    <parent link="link_3"/>
    <child link="link_4"/>
    <axis xyz="-1 0 0"/>
    <limit effort="0" lower="-3.141592653589793" upper="3.141592653589793" velocity="2.0943951023931953"/>
  </joint>
  <link name="tool0"/>
  <joint name="link_4-tool0" type="fixed">
    <origin rpy="0 0 0" xyz="0 0 0.0943"/>
    <parent link="link_4"/>
    <child link="tool0"/>
  </joint>
  <link name="tip"/>
  <joint name="tool0-tip" type="fixed">
    <origin rpy="0 0 0" xyz="0 -0.075 0"/>
    <parent link="tool0"/>
    <child link="tip"/>
  </joint>
  <link name="base_elevation">
    <visual>
      <origin rpy="0 0 0" xyz="0 0 0"/>
      <geometry>
        <mesh filename="package://sketch_bot_support/meshes/visual/base_elevation.stl" scale="1.0 1.0 1.0"/>
      </geometry>
      <material name="white"/>
    </visual>
    <collision>
      <origin rpy="0 0 0" xyz="0 0 0"/>
      <geometry>
        <mesh filename="package://sketch_bot_support/meshes/collision/base_elevation.stl" scale="1.0 1.0 1.0"/>
      </geometry>
    </collision>
  </link>
  <joint name="base_elevation-base_link" type="fixed">
    <origin rpy="0 0 0" xyz="0 0 0"/>
    <parent link="base_elevation"/>
    <child link="base_link"/>
  </joint>
</robot>
